[2024-07-22T16:15:03.098+0000] {taskinstance.py:1956} INFO - Dependencies all met for dep_context=non-requeueable deps ti=<TaskInstance: fact_order_product_etl_daily.transform_and_load_task scheduled__2024-07-21T00:00:00+00:00 [queued]>
[2024-07-22T16:15:03.111+0000] {taskinstance.py:1956} INFO - Dependencies all met for dep_context=requeueable deps ti=<TaskInstance: fact_order_product_etl_daily.transform_and_load_task scheduled__2024-07-21T00:00:00+00:00 [queued]>
[2024-07-22T16:15:03.112+0000] {taskinstance.py:2170} INFO - Starting attempt 1 of 1
[2024-07-22T16:15:03.132+0000] {taskinstance.py:2191} INFO - Executing <Task(_PythonDecoratedOperator): transform_and_load_task> on 2024-07-21 00:00:00+00:00
[2024-07-22T16:15:03.142+0000] {standard_task_runner.py:60} INFO - Started process 549 to run task
[2024-07-22T16:15:03.147+0000] {standard_task_runner.py:87} INFO - Running: ['***', 'tasks', 'run', 'fact_order_product_etl_daily', 'transform_and_load_task', 'scheduled__2024-07-21T00:00:00+00:00', '--job-id', '246', '--raw', '--subdir', 'DAGS_FOLDER/fact_order_product.py', '--cfg-path', '/tmp/tmplqqbcna_']
[2024-07-22T16:15:03.150+0000] {standard_task_runner.py:88} INFO - Job 246: Subtask transform_and_load_task
[2024-07-22T16:15:03.224+0000] {task_command.py:423} INFO - Running <TaskInstance: fact_order_product_etl_daily.transform_and_load_task scheduled__2024-07-21T00:00:00+00:00 [running]> on host 087c584822ad
[2024-07-22T16:15:03.368+0000] {taskinstance.py:2480} INFO - Exporting env vars: AIRFLOW_CTX_DAG_OWNER='***' AIRFLOW_CTX_DAG_ID='fact_order_product_etl_daily' AIRFLOW_CTX_TASK_ID='transform_and_load_task' AIRFLOW_CTX_EXECUTION_DATE='2024-07-21T00:00:00+00:00' AIRFLOW_CTX_TRY_NUMBER='1' AIRFLOW_CTX_DAG_RUN_ID='scheduled__2024-07-21T00:00:00+00:00'
[2024-07-22T16:15:03.380+0000] {pipeline.py:197} INFO - Missing pipeline option (runner). Executing pipeline using the default runner: DirectRunner.
[2024-07-22T16:15:05.117+0000] {taskinstance.py:2698} ERROR - Task failed with exception
Traceback (most recent call last):
  File "/home/airflow/.local/lib/python3.8/site-packages/airflow/models/taskinstance.py", line 433, in _execute_task
    result = execute_callable(context=context, **execute_callable_kwargs)
  File "/home/airflow/.local/lib/python3.8/site-packages/airflow/decorators/base.py", line 241, in execute
    return_value = super().execute(context)
  File "/home/airflow/.local/lib/python3.8/site-packages/airflow/operators/python.py", line 199, in execute
    return_value = self.execute_callable()
  File "/home/airflow/.local/lib/python3.8/site-packages/airflow/operators/python.py", line 216, in execute_callable
    return self.python_callable(*self.op_args, **self.op_kwargs)
  File "/opt/airflow/dags/fact_order_product.py", line 73, in transform_and_load_task
    p
  File "/home/airflow/.local/lib/python3.8/site-packages/apache_beam/transforms/ptransform.py", line 1110, in __ror__
    return self.transform.__ror__(pvalueish, self.label)
  File "/home/airflow/.local/lib/python3.8/site-packages/apache_beam/transforms/ptransform.py", line 616, in __ror__
    replacements = {
  File "/home/airflow/.local/lib/python3.8/site-packages/apache_beam/transforms/ptransform.py", line 617, in <dictcomp>
    id(v): p | 'CreatePInput%s' % ix >> Create(v, reshuffle=False)
  File "/home/airflow/.local/lib/python3.8/site-packages/apache_beam/transforms/core.py", line 3737, in __init__
    self.values = tuple(values)
  File "/home/airflow/.local/lib/python3.8/site-packages/apache_beam/io/gcp/bigquery.py", line 2483, in __getitem__
    raise AttributeError(
AttributeError: Error trying to access nonexistent attribute `0` in write result. Please see __documentation__ for available attributes.
[2024-07-22T16:15:05.154+0000] {taskinstance.py:1138} INFO - Marking task as FAILED. dag_id=fact_order_product_etl_daily, task_id=transform_and_load_task, execution_date=20240721T000000, start_date=20240722T161503, end_date=20240722T161505
[2024-07-22T16:15:05.184+0000] {standard_task_runner.py:107} ERROR - Failed to execute job 246 for task transform_and_load_task (Error trying to access nonexistent attribute `0` in write result. Please see __documentation__ for available attributes.; 549)
[2024-07-22T16:15:05.206+0000] {local_task_job_runner.py:234} INFO - Task exited with return code 1
[2024-07-22T16:15:05.239+0000] {taskinstance.py:3280} INFO - 0 downstream tasks scheduled from follow-on schedule check
