[2024-07-21T15:31:07.886+0000] {taskinstance.py:1956} INFO - Dependencies all met for dep_context=non-requeueable deps ti=<TaskInstance: dim_customer.ingest_data_task manual__2024-07-21T15:30:58.810975+00:00 [queued]>
[2024-07-21T15:31:07.899+0000] {taskinstance.py:1956} INFO - Dependencies all met for dep_context=requeueable deps ti=<TaskInstance: dim_customer.ingest_data_task manual__2024-07-21T15:30:58.810975+00:00 [queued]>
[2024-07-21T15:31:07.900+0000] {taskinstance.py:2170} INFO - Starting attempt 1 of 1
[2024-07-21T15:31:07.919+0000] {taskinstance.py:2191} INFO - Executing <Task(_PythonDecoratedOperator): ingest_data_task> on 2024-07-21 15:30:58.810975+00:00
[2024-07-21T15:31:07.931+0000] {standard_task_runner.py:60} INFO - Started process 6643 to run task
[2024-07-21T15:31:07.941+0000] {standard_task_runner.py:87} INFO - Running: ['***', 'tasks', 'run', 'dim_customer', 'ingest_data_task', 'manual__2024-07-21T15:30:58.810975+00:00', '--job-id', '182', '--raw', '--subdir', 'DAGS_FOLDER/dim_customer.py', '--cfg-path', '/tmp/tmpny7rrsen']
[2024-07-21T15:31:07.947+0000] {standard_task_runner.py:88} INFO - Job 182: Subtask ingest_data_task
[2024-07-21T15:31:08.071+0000] {task_command.py:423} INFO - Running <TaskInstance: dim_customer.ingest_data_task manual__2024-07-21T15:30:58.810975+00:00 [running]> on host 087c584822ad
[2024-07-21T15:31:08.179+0000] {taskinstance.py:2480} INFO - Exporting env vars: AIRFLOW_CTX_DAG_OWNER='***' AIRFLOW_CTX_DAG_ID='dim_customer' AIRFLOW_CTX_TASK_ID='ingest_data_task' AIRFLOW_CTX_EXECUTION_DATE='2024-07-21T15:30:58.810975+00:00' AIRFLOW_CTX_TRY_NUMBER='1' AIRFLOW_CTX_DAG_RUN_ID='manual__2024-07-21T15:30:58.810975+00:00'
[2024-07-21T15:31:08.181+0000] {logging_mixin.py:188} INFO - Start data ingestion stage
[2024-07-21T15:31:11.903+0000] {logging_mixin.py:188} INFO - Number records captured: 175
[2024-07-21T15:31:11.911+0000] {logging_mixin.py:188} INFO - created_at         datetime64[ns]
last_updated_at    datetime64[ns]
customer_id                 int64
customer_name              object
email                      object
phone                      object
city_id                     int64
address_details            object
dtype: object
[2024-07-21T15:31:11.948+0000] {taskinstance.py:2698} ERROR - Task failed with exception
Traceback (most recent call last):
  File "fastavro/_write.pyx", line 130, in fastavro._write.write_utf8
AttributeError: 'NoneType' object has no attribute 'encode'

During handling of the above exception, another exception occurred:

Traceback (most recent call last):
  File "fastavro/_write.pyx", line 431, in fastavro._write.write_data
  File "fastavro/_write.pyx", line 132, in fastavro._write.write_utf8
TypeError: must be string

During handling of the above exception, another exception occurred:

Traceback (most recent call last):
  File "/home/airflow/.local/lib/python3.8/site-packages/airflow/models/taskinstance.py", line 433, in _execute_task
    result = execute_callable(context=context, **execute_callable_kwargs)
  File "/home/airflow/.local/lib/python3.8/site-packages/airflow/decorators/base.py", line 241, in execute
    return_value = super().execute(context)
  File "/home/airflow/.local/lib/python3.8/site-packages/airflow/operators/python.py", line 199, in execute
    return_value = self.execute_callable()
  File "/home/airflow/.local/lib/python3.8/site-packages/airflow/operators/python.py", line 216, in execute_callable
    return self.python_callable(*self.op_args, **self.op_kwargs)
  File "/opt/airflow/dags/dim_customer.py", line 29, in ingest_data_task
    ingest_data(db_table_name)
  File "/opt/airflow/plugins/my_modules/ingestion_stage.py", line 126, in ingest_data
    capture_data_change(pool,table_name)
  File "/opt/airflow/plugins/my_modules/ingestion_stage.py", line 101, in capture_data_change
    fastavro.writer(file,schema,records)
  File "fastavro/_write.pyx", line 790, in fastavro._write.writer
  File "fastavro/_write.pyx", line 732, in fastavro._write.Writer.write
  File "fastavro/_write.pyx", line 469, in fastavro._write.write_data
  File "fastavro/_write.pyx", line 459, in fastavro._write.write_data
  File "fastavro/_write.pyx", line 403, in fastavro._write.write_record
  File "fastavro/_write.pyx", line 468, in fastavro._write.write_data
  File "fastavro/_write.pyx", line 431, in fastavro._write.write_data
  File "fastavro/_write.pyx", line 132, in fastavro._write.write_utf8
TypeError: must be string on field phone
[2024-07-21T15:31:12.003+0000] {taskinstance.py:1138} INFO - Marking task as FAILED. dag_id=dim_customer, task_id=ingest_data_task, execution_date=20240721T153058, start_date=20240721T153107, end_date=20240721T153112
[2024-07-21T15:31:12.052+0000] {standard_task_runner.py:107} ERROR - Failed to execute job 182 for task ingest_data_task (must be string on field phone; 6643)
[2024-07-21T15:31:12.100+0000] {local_task_job_runner.py:234} INFO - Task exited with return code 1
[2024-07-21T15:31:12.166+0000] {taskinstance.py:3280} INFO - 0 downstream tasks scheduled from follow-on schedule check
