[2024-07-21T10:51:49.147+0000] {taskinstance.py:1956} INFO - Dependencies all met for dep_context=non-requeueable deps ti=<TaskInstance: dim_product.ingest_data_task manual__2024-07-21T10:51:32.665571+00:00 [queued]>
[2024-07-21T10:51:49.161+0000] {taskinstance.py:1956} INFO - Dependencies all met for dep_context=requeueable deps ti=<TaskInstance: dim_product.ingest_data_task manual__2024-07-21T10:51:32.665571+00:00 [queued]>
[2024-07-21T10:51:49.162+0000] {taskinstance.py:2170} INFO - Starting attempt 1 of 1
[2024-07-21T10:51:49.183+0000] {taskinstance.py:2191} INFO - Executing <Task(_PythonDecoratedOperator): ingest_data_task> on 2024-07-21 10:51:32.665571+00:00
[2024-07-21T10:51:49.194+0000] {standard_task_runner.py:60} INFO - Started process 2441 to run task
[2024-07-21T10:51:49.200+0000] {standard_task_runner.py:87} INFO - Running: ['***', 'tasks', 'run', 'dim_product', 'ingest_data_task', 'manual__2024-07-21T10:51:32.665571+00:00', '--job-id', '160', '--raw', '--subdir', 'DAGS_FOLDER/dim_product_orchestration.py', '--cfg-path', '/tmp/tmpdzu_h0wn']
[2024-07-21T10:51:49.202+0000] {standard_task_runner.py:88} INFO - Job 160: Subtask ingest_data_task
[2024-07-21T10:51:49.277+0000] {task_command.py:423} INFO - Running <TaskInstance: dim_product.ingest_data_task manual__2024-07-21T10:51:32.665571+00:00 [running]> on host 087c584822ad
[2024-07-21T10:51:49.408+0000] {taskinstance.py:2480} INFO - Exporting env vars: AIRFLOW_CTX_DAG_OWNER='***' AIRFLOW_CTX_DAG_ID='dim_product' AIRFLOW_CTX_TASK_ID='ingest_data_task' AIRFLOW_CTX_EXECUTION_DATE='2024-07-21T10:51:32.665571+00:00' AIRFLOW_CTX_TRY_NUMBER='1' AIRFLOW_CTX_DAG_RUN_ID='manual__2024-07-21T10:51:32.665571+00:00'
[2024-07-21T10:51:54.655+0000] {taskinstance.py:2698} ERROR - Task failed with exception
Traceback (most recent call last):
  File "/home/airflow/.local/lib/python3.8/site-packages/sqlalchemy/engine/base.py", line 1910, in _execute_context
    self.dialect.do_execute(
  File "/home/airflow/.local/lib/python3.8/site-packages/sqlalchemy/engine/default.py", line 736, in do_execute
    cursor.execute(statement, parameters)
  File "/home/airflow/.local/lib/python3.8/site-packages/pg8000/dbapi.py", line 468, in execute
    self._context = self._c.execute_simple(operation)
  File "/home/airflow/.local/lib/python3.8/site-packages/pg8000/core.py", line 686, in execute_simple
    self.handle_messages(context)
  File "/home/airflow/.local/lib/python3.8/site-packages/pg8000/core.py", line 835, in handle_messages
    raise context.error
pg8000.exceptions.DatabaseError: {'S': 'ERROR', 'V': 'ERROR', 'C': '42601', 'M': 'syntax error at or near "\'product_stg\'"', 'P': '15', 'F': 'scan.l', 'L': '1192', 'R': 'scanner_yyerror'}

The above exception was the direct cause of the following exception:

Traceback (most recent call last):
  File "/home/airflow/.local/lib/python3.8/site-packages/airflow/models/taskinstance.py", line 433, in _execute_task
    result = execute_callable(context=context, **execute_callable_kwargs)
  File "/home/airflow/.local/lib/python3.8/site-packages/airflow/decorators/base.py", line 241, in execute
    return_value = super().execute(context)
  File "/home/airflow/.local/lib/python3.8/site-packages/airflow/operators/python.py", line 199, in execute
    return_value = self.execute_callable()
  File "/home/airflow/.local/lib/python3.8/site-packages/airflow/operators/python.py", line 216, in execute_callable
    return self.python_callable(*self.op_args, **self.op_kwargs)
  File "/opt/airflow/dags/dim_product_orchestration.py", line 29, in ingest_data_task
    ingest_data(db_table_name)
  File "/opt/airflow/plugins/my_modules/ingestion_stage.py", line 118, in ingest_data
    capture_data_change(pool,table_name)
  File "/opt/airflow/plugins/my_modules/ingestion_stage.py", line 69, in capture_data_change
    capture_data_change_df = pd.read_sql_query(
  File "/home/airflow/.local/lib/python3.8/site-packages/pandas/io/sql.py", line 469, in read_sql_query
    return pandas_sql.read_query(
  File "/home/airflow/.local/lib/python3.8/site-packages/pandas/io/sql.py", line 1738, in read_query
    result = self.execute(sql, params)
  File "/home/airflow/.local/lib/python3.8/site-packages/pandas/io/sql.py", line 1562, in execute
    return self.con.exec_driver_sql(sql, *args)
  File "/home/airflow/.local/lib/python3.8/site-packages/sqlalchemy/engine/base.py", line 1770, in exec_driver_sql
    return self._exec_driver_sql(
  File "/home/airflow/.local/lib/python3.8/site-packages/sqlalchemy/engine/base.py", line 1674, in _exec_driver_sql
    ret = self._execute_context(
  File "/home/airflow/.local/lib/python3.8/site-packages/sqlalchemy/engine/base.py", line 1953, in _execute_context
    self._handle_dbapi_exception(
  File "/home/airflow/.local/lib/python3.8/site-packages/sqlalchemy/engine/base.py", line 2134, in _handle_dbapi_exception
    util.raise_(
  File "/home/airflow/.local/lib/python3.8/site-packages/sqlalchemy/util/compat.py", line 211, in raise_
    raise exception
  File "/home/airflow/.local/lib/python3.8/site-packages/sqlalchemy/engine/base.py", line 1910, in _execute_context
    self.dialect.do_execute(
  File "/home/airflow/.local/lib/python3.8/site-packages/sqlalchemy/engine/default.py", line 736, in do_execute
    cursor.execute(statement, parameters)
  File "/home/airflow/.local/lib/python3.8/site-packages/pg8000/dbapi.py", line 468, in execute
    self._context = self._c.execute_simple(operation)
  File "/home/airflow/.local/lib/python3.8/site-packages/pg8000/core.py", line 686, in execute_simple
    self.handle_messages(context)
  File "/home/airflow/.local/lib/python3.8/site-packages/pg8000/core.py", line 835, in handle_messages
    raise context.error
sqlalchemy.exc.DatabaseError: (pg8000.exceptions.DatabaseError) {'S': 'ERROR', 'V': 'ERROR', 'C': '42601', 'M': 'syntax error at or near "\'product_stg\'"', 'P': '15', 'F': 'scan.l', 'L': '1192', 'R': 'scanner_yyerror'}
[SQL: select * from 'product_stg' where last_updated_at >= '01/01/2024 0:00:00 AM +00:00']
(Background on this error at: https://sqlalche.me/e/14/4xp6)
[2024-07-21T10:51:54.717+0000] {taskinstance.py:1138} INFO - Marking task as FAILED. dag_id=dim_product, task_id=ingest_data_task, execution_date=20240721T105132, start_date=20240721T105149, end_date=20240721T105154
[2024-07-21T10:51:54.750+0000] {standard_task_runner.py:107} ERROR - Failed to execute job 160 for task ingest_data_task ((pg8000.exceptions.DatabaseError) {'S': 'ERROR', 'V': 'ERROR', 'C': '42601', 'M': 'syntax error at or near "\'product_stg\'"', 'P': '15', 'F': 'scan.l', 'L': '1192', 'R': 'scanner_yyerror'}
[SQL: select * from 'product_stg' where last_updated_at >= '01/01/2024 0:00:00 AM +00:00']
(Background on this error at: https://sqlalche.me/e/14/4xp6); 2441)
[2024-07-21T10:51:54.772+0000] {local_task_job_runner.py:234} INFO - Task exited with return code 1
[2024-07-21T10:51:54.807+0000] {taskinstance.py:3280} INFO - 0 downstream tasks scheduled from follow-on schedule check
