[2024-07-16T03:06:27.231+0000] {taskinstance.py:1956} INFO - Dependencies all met for dep_context=non-requeueable deps ti=<TaskInstance: dim_product.ingest_data_task scheduled__2024-07-15T00:00:00+00:00 [queued]>
[2024-07-16T03:06:27.250+0000] {taskinstance.py:1956} INFO - Dependencies all met for dep_context=requeueable deps ti=<TaskInstance: dim_product.ingest_data_task scheduled__2024-07-15T00:00:00+00:00 [queued]>
[2024-07-16T03:06:27.254+0000] {taskinstance.py:2170} INFO - Starting attempt 1 of 1
[2024-07-16T03:06:27.281+0000] {taskinstance.py:2191} INFO - Executing <Task(_PythonDecoratedOperator): ingest_data_task> on 2024-07-15 00:00:00+00:00
[2024-07-16T03:06:27.299+0000] {standard_task_runner.py:87} INFO - Running: ['***', 'tasks', 'run', 'dim_product', 'ingest_data_task', 'scheduled__2024-07-15T00:00:00+00:00', '--job-id', '21', '--raw', '--subdir', 'DAGS_FOLDER/dim_product_orchestration.py', '--cfg-path', '/tmp/tmp1ek2sr8p']
[2024-07-16T03:06:27.302+0000] {standard_task_runner.py:88} INFO - Job 21: Subtask ingest_data_task
[2024-07-16T03:06:27.295+0000] {standard_task_runner.py:60} INFO - Started process 226 to run task
[2024-07-16T03:06:27.416+0000] {task_command.py:423} INFO - Running <TaskInstance: dim_product.ingest_data_task scheduled__2024-07-15T00:00:00+00:00 [running]> on host d25b3dd9bd72
[2024-07-16T03:06:27.598+0000] {taskinstance.py:2480} INFO - Exporting env vars: AIRFLOW_CTX_DAG_OWNER='***' AIRFLOW_CTX_DAG_ID='dim_product' AIRFLOW_CTX_TASK_ID='ingest_data_task' AIRFLOW_CTX_EXECUTION_DATE='2024-07-15T00:00:00+00:00' AIRFLOW_CTX_TRY_NUMBER='1' AIRFLOW_CTX_DAG_RUN_ID='scheduled__2024-07-15T00:00:00+00:00'
[2024-07-16T03:06:27.728+0000] {_metadata.py:139} WARNING - Compute Engine Metadata server unavailable on attempt 1 of 3. Reason: [Errno 111] Connection refused
[2024-07-16T03:06:27.740+0000] {_metadata.py:139} WARNING - Compute Engine Metadata server unavailable on attempt 2 of 3. Reason: [Errno 111] Connection refused
[2024-07-16T03:06:27.761+0000] {_metadata.py:139} WARNING - Compute Engine Metadata server unavailable on attempt 3 of 3. Reason: [Errno 111] Connection refused
[2024-07-16T03:06:27.774+0000] {_default.py:338} WARNING - Authentication failed using Compute Engine authentication due to unavailable metadata server.
[2024-07-16T03:06:27.785+0000] {taskinstance.py:2698} ERROR - Task failed with exception
Traceback (most recent call last):
  File "/home/airflow/.local/lib/python3.8/site-packages/airflow/models/taskinstance.py", line 433, in _execute_task
    result = execute_callable(context=context, **execute_callable_kwargs)
  File "/home/airflow/.local/lib/python3.8/site-packages/airflow/decorators/base.py", line 241, in execute
    return_value = super().execute(context)
  File "/home/airflow/.local/lib/python3.8/site-packages/airflow/operators/python.py", line 199, in execute
    return_value = self.execute_callable()
  File "/home/airflow/.local/lib/python3.8/site-packages/airflow/operators/python.py", line 216, in execute_callable
    return self.python_callable(*self.op_args, **self.op_kwargs)
  File "/opt/airflow/dags/dim_product_orchestration.py", line 20, in ingest_data_task
    ingest_data()
  File "/opt/airflow/plugins/modules/ingestion_stage.py", line 122, in ingest_data
    capture_data_change(pool)
  File "/opt/airflow/plugins/modules/ingestion_stage.py", line 56, in capture_data_change
    last_updated_ts_df = get_last_updated_ts()
  File "/opt/airflow/plugins/modules/ingestion_stage.py", line 49, in get_last_updated_ts
    storage_client = storage.Client()
  File "/home/airflow/.local/lib/python3.8/site-packages/google/cloud/storage/client.py", line 226, in __init__
    super(Client, self).__init__(
  File "/home/airflow/.local/lib/python3.8/site-packages/google/cloud/client/__init__.py", line 320, in __init__
    _ClientProjectMixin.__init__(self, project=project, credentials=credentials)
  File "/home/airflow/.local/lib/python3.8/site-packages/google/cloud/client/__init__.py", line 268, in __init__
    project = self._determine_default(project)
  File "/home/airflow/.local/lib/python3.8/site-packages/google/cloud/client/__init__.py", line 287, in _determine_default
    return _determine_default_project(project)
  File "/home/airflow/.local/lib/python3.8/site-packages/google/cloud/_helpers/__init__.py", line 152, in _determine_default_project
    _, project = google.auth.default()
  File "/home/airflow/.local/lib/python3.8/site-packages/google/auth/_default.py", line 691, in default
    raise exceptions.DefaultCredentialsError(_CLOUD_SDK_MISSING_CREDENTIALS)
google.auth.exceptions.DefaultCredentialsError: Your default credentials were not found. To set up Application Default Credentials, see https://cloud.google.com/docs/authentication/external/set-up-adc for more information.
[2024-07-16T03:06:27.829+0000] {taskinstance.py:1138} INFO - Marking task as FAILED. dag_id=dim_product, task_id=ingest_data_task, execution_date=20240715T000000, start_date=20240716T030627, end_date=20240716T030627
[2024-07-16T03:06:27.924+0000] {standard_task_runner.py:107} ERROR - Failed to execute job 21 for task ingest_data_task (Your default credentials were not found. To set up Application Default Credentials, see https://cloud.google.com/docs/authentication/external/set-up-adc for more information.; 226)
[2024-07-16T03:06:27.963+0000] {local_task_job_runner.py:234} INFO - Task exited with return code 1
[2024-07-16T03:06:28.022+0000] {taskinstance.py:3280} INFO - 0 downstream tasks scheduled from follow-on schedule check
