[2024-07-16T05:10:57.080+0000] {taskinstance.py:1956} INFO - Dependencies all met for dep_context=non-requeueable deps ti=<TaskInstance: dim_product.ingest_data_task manual__2024-07-16T05:10:53.826680+00:00 [queued]>
[2024-07-16T05:10:57.090+0000] {taskinstance.py:1956} INFO - Dependencies all met for dep_context=requeueable deps ti=<TaskInstance: dim_product.ingest_data_task manual__2024-07-16T05:10:53.826680+00:00 [queued]>
[2024-07-16T05:10:57.091+0000] {taskinstance.py:2170} INFO - Starting attempt 1 of 1
[2024-07-16T05:10:57.107+0000] {taskinstance.py:2191} INFO - Executing <Task(_PythonDecoratedOperator): ingest_data_task> on 2024-07-16 05:10:53.826680+00:00
[2024-07-16T05:10:57.115+0000] {standard_task_runner.py:60} INFO - Started process 562 to run task
[2024-07-16T05:10:57.119+0000] {standard_task_runner.py:87} INFO - Running: ['***', 'tasks', 'run', 'dim_product', 'ingest_data_task', 'manual__2024-07-16T05:10:53.826680+00:00', '--job-id', '64', '--raw', '--subdir', 'DAGS_FOLDER/dim_product_orchestration.py', '--cfg-path', '/tmp/tmpcn7fxmj_']
[2024-07-16T05:10:57.121+0000] {standard_task_runner.py:88} INFO - Job 64: Subtask ingest_data_task
[2024-07-16T05:10:57.181+0000] {task_command.py:423} INFO - Running <TaskInstance: dim_product.ingest_data_task manual__2024-07-16T05:10:53.826680+00:00 [running]> on host 016096cb41a6
[2024-07-16T05:10:57.264+0000] {taskinstance.py:2480} INFO - Exporting env vars: AIRFLOW_CTX_DAG_OWNER='***' AIRFLOW_CTX_DAG_ID='dim_product' AIRFLOW_CTX_TASK_ID='ingest_data_task' AIRFLOW_CTX_EXECUTION_DATE='2024-07-16T05:10:53.826680+00:00' AIRFLOW_CTX_TRY_NUMBER='1' AIRFLOW_CTX_DAG_RUN_ID='manual__2024-07-16T05:10:53.826680+00:00'
[2024-07-16T05:10:58.513+0000] {taskinstance.py:2698} ERROR - Task failed with exception
Traceback (most recent call last):
  File "/home/airflow/.local/lib/python3.8/site-packages/airflow/models/taskinstance.py", line 433, in _execute_task
    result = execute_callable(context=context, **execute_callable_kwargs)
  File "/home/airflow/.local/lib/python3.8/site-packages/airflow/decorators/base.py", line 241, in execute
    return_value = super().execute(context)
  File "/home/airflow/.local/lib/python3.8/site-packages/airflow/operators/python.py", line 199, in execute
    return_value = self.execute_callable()
  File "/home/airflow/.local/lib/python3.8/site-packages/airflow/operators/python.py", line 216, in execute_callable
    return self.python_callable(*self.op_args, **self.op_kwargs)
  File "/opt/airflow/dags/dim_product_orchestration.py", line 20, in ingest_data_task
    ingest_data()
  File "/opt/airflow/plugins/modules/ingestion_stage.py", line 122, in ingest_data
    capture_data_change(pool)
  File "/opt/airflow/plugins/modules/ingestion_stage.py", line 60, in capture_data_change
    capture_data_change_df = pd.read_sql_query(
  File "/home/airflow/.local/lib/python3.8/site-packages/pandas/io/sql.py", line 468, in read_sql_query
    with pandasSQL_builder(con) as pandas_sql:
  File "/home/airflow/.local/lib/python3.8/site-packages/pandas/io/sql.py", line 832, in pandasSQL_builder
    return SQLDatabase(con, schema, need_transaction)
  File "/home/airflow/.local/lib/python3.8/site-packages/pandas/io/sql.py", line 1539, in __init__
    con = self.exit_stack.enter_context(con.connect())
  File "/home/airflow/.local/lib/python3.8/site-packages/sqlalchemy/engine/base.py", line 3325, in connect
    return self._connection_cls(self, close_with_result=close_with_result)
  File "/home/airflow/.local/lib/python3.8/site-packages/sqlalchemy/engine/base.py", line 96, in __init__
    else engine.raw_connection()
  File "/home/airflow/.local/lib/python3.8/site-packages/sqlalchemy/engine/base.py", line 3404, in raw_connection
    return self._wrap_pool_connect(self.pool.connect, _connection)
  File "/home/airflow/.local/lib/python3.8/site-packages/sqlalchemy/engine/base.py", line 3371, in _wrap_pool_connect
    return fn()
  File "/home/airflow/.local/lib/python3.8/site-packages/sqlalchemy/pool/base.py", line 327, in connect
    return _ConnectionFairy._checkout(self)
  File "/home/airflow/.local/lib/python3.8/site-packages/sqlalchemy/pool/base.py", line 894, in _checkout
    fairy = _ConnectionRecord.checkout(pool)
  File "/home/airflow/.local/lib/python3.8/site-packages/sqlalchemy/pool/base.py", line 493, in checkout
    rec = pool._do_get()
  File "/home/airflow/.local/lib/python3.8/site-packages/sqlalchemy/pool/impl.py", line 146, in _do_get
    self._dec_overflow()
  File "/home/airflow/.local/lib/python3.8/site-packages/sqlalchemy/util/langhelpers.py", line 70, in __exit__
    compat.raise_(
  File "/home/airflow/.local/lib/python3.8/site-packages/sqlalchemy/util/compat.py", line 211, in raise_
    raise exception
  File "/home/airflow/.local/lib/python3.8/site-packages/sqlalchemy/pool/impl.py", line 143, in _do_get
    return self._create_connection()
  File "/home/airflow/.local/lib/python3.8/site-packages/sqlalchemy/pool/base.py", line 273, in _create_connection
    return _ConnectionRecord(self)
  File "/home/airflow/.local/lib/python3.8/site-packages/sqlalchemy/pool/base.py", line 388, in __init__
    self.__connect()
  File "/home/airflow/.local/lib/python3.8/site-packages/sqlalchemy/pool/base.py", line 691, in __connect
    pool.logger.debug("Error on connect(): %s", e)
  File "/home/airflow/.local/lib/python3.8/site-packages/sqlalchemy/util/langhelpers.py", line 70, in __exit__
    compat.raise_(
  File "/home/airflow/.local/lib/python3.8/site-packages/sqlalchemy/util/compat.py", line 211, in raise_
    raise exception
  File "/home/airflow/.local/lib/python3.8/site-packages/sqlalchemy/pool/base.py", line 686, in __connect
    self.dbapi_connection = connection = pool._invoke_creator(self)
  File "/home/airflow/.local/lib/python3.8/site-packages/sqlalchemy/pool/base.py", line 250, in <lambda>
    return lambda crec: creator()
  File "/opt/airflow/plugins/modules/ingestion_stage.py", line 33, in get_con
    instance, config = load_config()
  File "/opt/airflow/plugins/modules/ingestion_stage.py", line 24, in load_config
    raise Exception('Section {0} not found in the {1} file'.format(section, filename))
Exception: Section GSQL not found in the /plugins/modules/database.ini file
[2024-07-16T05:10:58.534+0000] {taskinstance.py:1138} INFO - Marking task as FAILED. dag_id=dim_product, task_id=ingest_data_task, execution_date=20240716T051053, start_date=20240716T051057, end_date=20240716T051058
[2024-07-16T05:10:58.555+0000] {standard_task_runner.py:107} ERROR - Failed to execute job 64 for task ingest_data_task (Section GSQL not found in the /plugins/modules/database.ini file; 562)
[2024-07-16T05:10:58.578+0000] {local_task_job_runner.py:234} INFO - Task exited with return code 1
[2024-07-16T05:10:58.611+0000] {taskinstance.py:3280} INFO - 0 downstream tasks scheduled from follow-on schedule check
