[2024-07-21T15:19:36.307+0000] {taskinstance.py:1956} INFO - Dependencies all met for dep_context=non-requeueable deps ti=<TaskInstance: dim_customer.ingest_data_task manual__2024-07-21T15:19:29.584717+00:00 [queued]>
[2024-07-21T15:19:36.325+0000] {taskinstance.py:1956} INFO - Dependencies all met for dep_context=requeueable deps ti=<TaskInstance: dim_customer.ingest_data_task manual__2024-07-21T15:19:29.584717+00:00 [queued]>
[2024-07-21T15:19:36.327+0000] {taskinstance.py:2170} INFO - Starting attempt 1 of 1
[2024-07-21T15:19:36.357+0000] {taskinstance.py:2191} INFO - Executing <Task(_PythonDecoratedOperator): ingest_data_task> on 2024-07-21 15:19:29.584717+00:00
[2024-07-21T15:19:36.374+0000] {standard_task_runner.py:60} INFO - Started process 6468 to run task
[2024-07-21T15:19:36.382+0000] {standard_task_runner.py:87} INFO - Running: ['***', 'tasks', 'run', 'dim_customer', 'ingest_data_task', 'manual__2024-07-21T15:19:29.584717+00:00', '--job-id', '181', '--raw', '--subdir', 'DAGS_FOLDER/dim_customer.py', '--cfg-path', '/tmp/tmpurn1lxvp']
[2024-07-21T15:19:36.388+0000] {standard_task_runner.py:88} INFO - Job 181: Subtask ingest_data_task
[2024-07-21T15:19:36.512+0000] {task_command.py:423} INFO - Running <TaskInstance: dim_customer.ingest_data_task manual__2024-07-21T15:19:29.584717+00:00 [running]> on host 087c584822ad
[2024-07-21T15:19:36.672+0000] {taskinstance.py:2480} INFO - Exporting env vars: AIRFLOW_CTX_DAG_OWNER='***' AIRFLOW_CTX_DAG_ID='dim_customer' AIRFLOW_CTX_TASK_ID='ingest_data_task' AIRFLOW_CTX_EXECUTION_DATE='2024-07-21T15:19:29.584717+00:00' AIRFLOW_CTX_TRY_NUMBER='1' AIRFLOW_CTX_DAG_RUN_ID='manual__2024-07-21T15:19:29.584717+00:00'
[2024-07-21T15:19:36.675+0000] {logging_mixin.py:188} INFO - Start data ingestion stage
[2024-07-21T15:19:40.832+0000] {logging_mixin.py:188} INFO - Number records captured: 175
[2024-07-21T15:19:40.856+0000] {taskinstance.py:2698} ERROR - Task failed with exception
Traceback (most recent call last):
  File "fastavro/_write.pyx", line 130, in fastavro._write.write_utf8
AttributeError: 'NoneType' object has no attribute 'encode'

During handling of the above exception, another exception occurred:

Traceback (most recent call last):
  File "fastavro/_write.pyx", line 431, in fastavro._write.write_data
  File "fastavro/_write.pyx", line 132, in fastavro._write.write_utf8
TypeError: must be string

During handling of the above exception, another exception occurred:

Traceback (most recent call last):
  File "/home/airflow/.local/lib/python3.8/site-packages/airflow/models/taskinstance.py", line 433, in _execute_task
    result = execute_callable(context=context, **execute_callable_kwargs)
  File "/home/airflow/.local/lib/python3.8/site-packages/airflow/decorators/base.py", line 241, in execute
    return_value = super().execute(context)
  File "/home/airflow/.local/lib/python3.8/site-packages/airflow/operators/python.py", line 199, in execute
    return_value = self.execute_callable()
  File "/home/airflow/.local/lib/python3.8/site-packages/airflow/operators/python.py", line 216, in execute_callable
    return self.python_callable(*self.op_args, **self.op_kwargs)
  File "/opt/airflow/dags/dim_customer.py", line 29, in ingest_data_task
    ingest_data(db_table_name)
  File "/opt/airflow/plugins/my_modules/ingestion_stage.py", line 125, in ingest_data
    capture_data_change(pool,table_name)
  File "/opt/airflow/plugins/my_modules/ingestion_stage.py", line 100, in capture_data_change
    fastavro.writer(file,schema,records)
  File "fastavro/_write.pyx", line 790, in fastavro._write.writer
  File "fastavro/_write.pyx", line 732, in fastavro._write.Writer.write
  File "fastavro/_write.pyx", line 469, in fastavro._write.write_data
  File "fastavro/_write.pyx", line 459, in fastavro._write.write_data
  File "fastavro/_write.pyx", line 403, in fastavro._write.write_record
  File "fastavro/_write.pyx", line 468, in fastavro._write.write_data
  File "fastavro/_write.pyx", line 431, in fastavro._write.write_data
  File "fastavro/_write.pyx", line 132, in fastavro._write.write_utf8
TypeError: must be string on field phone
[2024-07-21T15:19:40.885+0000] {taskinstance.py:1138} INFO - Marking task as FAILED. dag_id=dim_customer, task_id=ingest_data_task, execution_date=20240721T151929, start_date=20240721T151936, end_date=20240721T151940
[2024-07-21T15:19:40.906+0000] {standard_task_runner.py:107} ERROR - Failed to execute job 181 for task ingest_data_task (must be string on field phone; 6468)
[2024-07-21T15:19:40.938+0000] {local_task_job_runner.py:234} INFO - Task exited with return code 1
[2024-07-21T15:19:40.964+0000] {taskinstance.py:3280} INFO - 0 downstream tasks scheduled from follow-on schedule check
