[2024-07-21T17:09:58.620+0000] {taskinstance.py:1956} INFO - Dependencies all met for dep_context=non-requeueable deps ti=<TaskInstance: fact_order.ingest_data_task manual__2024-07-21T17:09:52.652448+00:00 [queued]>
[2024-07-21T17:09:58.632+0000] {taskinstance.py:1956} INFO - Dependencies all met for dep_context=requeueable deps ti=<TaskInstance: fact_order.ingest_data_task manual__2024-07-21T17:09:52.652448+00:00 [queued]>
[2024-07-21T17:09:58.633+0000] {taskinstance.py:2170} INFO - Starting attempt 1 of 1
[2024-07-21T17:09:58.651+0000] {taskinstance.py:2191} INFO - Executing <Task(_PythonDecoratedOperator): ingest_data_task> on 2024-07-21 17:09:52.652448+00:00
[2024-07-21T17:09:58.664+0000] {standard_task_runner.py:60} INFO - Started process 8162 to run task
[2024-07-21T17:09:58.674+0000] {standard_task_runner.py:87} INFO - Running: ['***', 'tasks', 'run', 'fact_order', 'ingest_data_task', 'manual__2024-07-21T17:09:52.652448+00:00', '--job-id', '198', '--raw', '--subdir', 'DAGS_FOLDER/fact_order.py', '--cfg-path', '/tmp/tmpcupzq02i']
[2024-07-21T17:09:58.677+0000] {standard_task_runner.py:88} INFO - Job 198: Subtask ingest_data_task
[2024-07-21T17:09:58.780+0000] {task_command.py:423} INFO - Running <TaskInstance: fact_order.ingest_data_task manual__2024-07-21T17:09:52.652448+00:00 [running]> on host 087c584822ad
[2024-07-21T17:09:58.980+0000] {taskinstance.py:2480} INFO - Exporting env vars: AIRFLOW_CTX_DAG_OWNER='***' AIRFLOW_CTX_DAG_ID='fact_order' AIRFLOW_CTX_TASK_ID='ingest_data_task' AIRFLOW_CTX_EXECUTION_DATE='2024-07-21T17:09:52.652448+00:00' AIRFLOW_CTX_TRY_NUMBER='1' AIRFLOW_CTX_DAG_RUN_ID='manual__2024-07-21T17:09:52.652448+00:00'
[2024-07-21T17:09:58.990+0000] {logging_mixin.py:188} INFO - Start data ingestion stage
[2024-07-21T17:10:04.335+0000] {logging_mixin.py:188} INFO - Number records captured: 8002
[2024-07-21T17:10:04.563+0000] {taskinstance.py:2698} ERROR - Task failed with exception
Traceback (most recent call last):
  File "fastavro/_write.pyx", line 441, in fastavro._write.write_data
  File "<stringsource>", line 663, in View.MemoryView.memoryview_cwrapper
  File "<stringsource>", line 353, in View.MemoryView.memoryview.__cinit__
TypeError: a bytes-like object is required, not 'float'

During handling of the above exception, another exception occurred:

Traceback (most recent call last):
  File "/home/airflow/.local/lib/python3.8/site-packages/airflow/models/taskinstance.py", line 433, in _execute_task
    result = execute_callable(context=context, **execute_callable_kwargs)
  File "/home/airflow/.local/lib/python3.8/site-packages/airflow/decorators/base.py", line 241, in execute
    return_value = super().execute(context)
  File "/home/airflow/.local/lib/python3.8/site-packages/airflow/operators/python.py", line 199, in execute
    return_value = self.execute_callable()
  File "/home/airflow/.local/lib/python3.8/site-packages/airflow/operators/python.py", line 216, in execute_callable
    return self.python_callable(*self.op_args, **self.op_kwargs)
  File "/opt/airflow/dags/fact_order.py", line 29, in ingest_data_task
    ingest_data(db_table_name)
  File "/opt/airflow/plugins/my_modules/ingestion_stage.py", line 128, in ingest_data
    capture_data_change(pool,table_name)
  File "/opt/airflow/plugins/my_modules/ingestion_stage.py", line 103, in capture_data_change
    fastavro.writer(file,schema,records)
  File "fastavro/_write.pyx", line 790, in fastavro._write.writer
  File "fastavro/_write.pyx", line 732, in fastavro._write.Writer.write
  File "fastavro/_write.pyx", line 469, in fastavro._write.write_data
  File "fastavro/_write.pyx", line 459, in fastavro._write.write_data
  File "fastavro/_write.pyx", line 403, in fastavro._write.write_record
  File "fastavro/_write.pyx", line 468, in fastavro._write.write_data
  File "fastavro/_write.pyx", line 441, in fastavro._write.write_data
  File "<stringsource>", line 663, in View.MemoryView.memoryview_cwrapper
  File "<stringsource>", line 353, in View.MemoryView.memoryview.__cinit__
TypeError: a bytes-like object is required, not 'float' on field total_price
[2024-07-21T17:10:04.582+0000] {taskinstance.py:1138} INFO - Marking task as FAILED. dag_id=fact_order, task_id=ingest_data_task, execution_date=20240721T170952, start_date=20240721T170958, end_date=20240721T171004
[2024-07-21T17:10:04.604+0000] {standard_task_runner.py:107} ERROR - Failed to execute job 198 for task ingest_data_task (a bytes-like object is required, not 'float' on field total_price; 8162)
[2024-07-21T17:10:04.639+0000] {local_task_job_runner.py:234} INFO - Task exited with return code 1
[2024-07-21T17:10:04.683+0000] {taskinstance.py:3280} INFO - 0 downstream tasks scheduled from follow-on schedule check
